package exception_handling; // nested try and catch block

public class ExceptionHandling_14 {
}


/*
1.try within a try is known as nested try.
2.Sometimes a situation may arise where a part of a block may cause one error and the entire block
itself may cause another error.
3.Syntax :
try
{

       try
       {
            code that may throw exception
       }
       catch(ExceptionName obj)
       {
            catch block
       }
}
catch(ExceptionName obj)
{
  catch block
}
*/
